Workbook

Sheet IPSEC_BGP_XE_CONFIG
B1: DRAFT - IN TEST MODE: billgra@cisco.com | C1: INPUT YELLOW CELLS | D1: Example | F1: Generated Configuration
B2: BEST VIEWED IN FULL EXCEL CLIENT - not web | F2: =C4 -> CiscoIOSA-vHub-CentralUS | G2: =C5 -> CiscoIOSB-EastUS-Region
F3: =_cfg_parts!L3 -> crypto ikev2 proposal sse-proposal | G3: =_cfg_parts!Q3 -> crypto ikev2 proposal sse-proposal
B4: Router 1 Name | C4: CiscoIOSA-vHub-CentralUS | F4: =_cfg_parts!L4 -> encryption aes-gcm-256 | G4: =_cfg_parts!Q4 -> encryption aes-gcm-256
B5: Router 2 Name | C5: CiscoIOSB-EastUS-Region | F5: =_cfg_parts!L5 -> prf sha256 | G5: =_cfg_parts!Q5 -> prf sha256
F6: =_cfg_parts!L6 -> group 20 | G6: =_cfg_parts!Q6 -> group 20
B7: Router 1 | F7: =_cfg_parts!L7 -> ! | G7: =_cfg_parts!Q7 -> !
B8: SSE Head-End Primary IP | C8: 3.141.141.165 | D8: 5.5.5.5 | F8: =_cfg_parts!L8 -> crypto ikev2 policy sse-policy | G8: =_cfg_parts!Q8 -> crypto ikev2 policy sse-policy
B9: SSE Primary Tunnel ID | C9: 8363425-667481483 | D9: <ORGID>-<TUNNELID> | F9: =_cfg_parts!L9 -> proposal sse-proposal | G9: =_cfg_parts!Q9 -> proposal sse-proposal
B10: SSE Primary DC Name | C10: prod_aws_us-east-2_1_0 - COLUMBUS-1 | D10: Verify against NTG in SSE Admin UI | F10: =_cfg_parts!L10 -> ! | G10: =_cfg_parts!Q10 -> !
F11: =_cfg_parts!L11 -> crypto ikev2 keyring sse-kr | G11: =_cfg_parts!Q11 -> crypto ikev2 keyring sse-kr
B12: SSE Head-End Secondary IP | C12: 3.140.13.195 | D12: 6.6.6.6 | F12: =_cfg_parts!L12 -> peer sse-secondary | G12: =_cfg_parts!Q12 -> peer sse-secondary
B13: SSE Secondary Identity (prefix only) | C13: 8363425-667481484 | D13: test2 | F13: =_cfg_parts!L13 -> address 3.140.13.195 | G13: =_cfg_parts!Q13 -> address 3.140.13.195
B14: SSE Secondary DC Name | C14: prod_aws_us-east-2_1_1 - COLUMBUS-2 | D14: Verify against NTG in SSE Admin UI | F14: =_cfg_parts!L14 -> pre-shared-key local ll0wN3t3ng123456 | G14: =_cfg_parts!Q14 -> pre-shared-key local ll0wN3t3ng123456
F15: =_cfg_parts!L15 -> pre-shared-key remote ll0wN3t3ng123456 | G15: =_cfg_parts!Q15 -> pre-shared-key remote ll0wN3t3ng123456
B16: BGP RID (interface Gigabit Ethernet 1 IP address) | C16: 10.255.0.5 | D16: 9.9.9.9 | F16: =_cfg_parts!L16 -> ! | G16: =_cfg_parts!Q16 -> !
B17: Local ASN | C17: 65461 | D17: 65412 | F17: =_cfg_parts!L17 -> peer sse-primary | G17: =_cfg_parts!Q17 -> peer sse-primary
F18: =_cfg_parts!L18 -> address 3.141.141.165 | G18: =_cfg_parts!Q18 -> address 3.141.141.165
B19: Router 2 | F19: =_cfg_parts!L19 -> pre-shared-key local ll0wN3t3ng123456 | G19: =_cfg_parts!Q19 -> pre-shared-key local ll0wN3t3ng123456
B20: SSE Head-End Primary IP | C20: 3.141.141.165 | D20: 5.5.5.5 | F20: =_cfg_parts!L20 -> pre-shared-key remote ll0wN3t3ng123456 | G20: =_cfg_parts!Q20 -> pre-shared-key remote ll0wN3t3ng123456
B21: SSE Primary Identity (prefix only) | C21: 8363425-667398686 | D21: <ORGID>-<TUNNELID> | F21: =_cfg_parts!L21 -> ! | G21: =_cfg_parts!Q21 -> !
B22: SSE Primary DC Name | C22: prod_csc_us-west-1_1_0 - LOSANGELES-2 | D22: Verify against NTG in SSE Admin UI | F22: =_cfg_parts!L22 -> ! | G22: =_cfg_parts!Q22 -> !
F23: =_cfg_parts!L23 -> ! | G23: =_cfg_parts!Q23 -> !
B24: SSE Head-End Secondary IP | C24: 3.140.13.195 | D24: 5.5.5.5 | F24: =_cfg_parts!L24 -> crypto ikev2 profile sse-primary-1 | G24: =_cfg_parts!Q24 -> crypto ikev2 profile sse-primary-1
B25: SSE Secondary Identity (prefix only) | C25: 8363425-667398687 | D25: test4 | F25: =_cfg_parts!L25 -> match identity remote address 3.141.141.165 255.255.255.255 | G25: =_cfg_parts!Q25 -> match identity remote address 3.141.141.165 255.255.255.255
B26: SSE Secondary DC Name | C26: prod_csc_us-west-1_1_1 - SANJOSE-6 | D26: Verify against NTG in SSE Admin UI | F26: =_cfg_parts!L26 -> identity local email CiscoIOSA-vHub-CentralUS+tunnel1@8363425-667481483-sse.cisco.com | G26: =_cfg_parts!Q26 -> identity local email CiscoIOSB-EastUS-Region+tunnel1@8363425-667398686-sse.cisco.com
F27: =_cfg_parts!L27 -> authentication remote pre-share | G27: =_cfg_parts!Q27 -> authentication remote pre-share
B28: BGP RID (interface Gigabit Ethernet 1 IP address) | C28: 10.53.0.198 | D28: 9.9.9.9 | F28: =_cfg_parts!L28 -> authentication local pre-share | G28: =_cfg_parts!Q28 -> authentication local pre-share
B29: Local ASN | C29: 64517 | D29: 65412 | F29: =_cfg_parts!L29 -> keyring local sse-kr | G29: =_cfg_parts!Q29 -> keyring local sse-kr
F30: =_cfg_parts!L30 -> dpd 10 3 periodic | G30: =_cfg_parts!Q30 -> dpd 10 3 periodic
F31: =_cfg_parts!L31 -> ! | G31: =_cfg_parts!Q31 -> !
B32: Pre-Shared Key | C32: ll0wN3t3ng123456 | D32: ABCDEFGHIJKLMNO | F32: =_cfg_parts!L32 -> crypto ikev2 profile sse-primary-2 | G32: =_cfg_parts!Q32 -> crypto ikev2 profile sse-primary-2
F33: =_cfg_parts!L33 -> match identity remote address 3.141.141.165 255.255.255.255 | G33: =_cfg_parts!Q33 -> match identity remote address 3.141.141.165 255.255.255.255
B34: Tunnel IP Address Allocations | D34: Results | F34: =_cfg_parts!L34 -> identity local email CiscoIOSA-vHub-CentralUS+tunnel2@8363425-667481483-sse.cisco.com | G34: =_cfg_parts!Q34 -> identity local email CiscoIOSB-EastUS-Region+tunnel2@8363425-667398686-sse.cisco.com
B35: Router 1 | C35: 10.7.15.64 | D35: =_data!E42 -> 10.7.15.64 | F35: =_cfg_parts!L35 -> authentication remote pre-share | G35: =_cfg_parts!Q35 -> authentication remote pre-share
B36: /28 CIDR to support 20 total interfaces | D36: =_data!E43 -> 10.7.15.65 | F36: =_cfg_parts!L36 -> authentication local pre-share | G36: =_cfg_parts!Q36 -> authentication local pre-share
B37: Do not include mask information | D37: =_data!E44 -> 10.7.15.66 | F37: =_cfg_parts!L37 -> keyring local sse-kr | G37: =_cfg_parts!Q37 -> keyring local sse-kr
B38: This sheet only supports IP addresses that … | D38: =_data!E45 -> 10.7.15.67 | F38: =_cfg_parts!L38 -> dpd 10 3 periodic | G38: =_cfg_parts!Q38 -> dpd 10 3 periodic
B39: … fit within a /24 boundary (x.x.x.0--x.x.x.254) | D39: =_data!E46 -> 10.7.15.68 | F39: =_cfg_parts!L39 -> ! | G39: =_cfg_parts!Q39 -> !
D40: =_data!E47 -> 10.7.15.69 | F40: =_cfg_parts!L40 -> crypto ikev2 profile sse-secondary-1 | G40: =_cfg_parts!Q40 -> crypto ikev2 profile sse-secondary-1
...

Sheet Route Policy Docs

Sheet CFG_RESET

Sheet COMM
A1: BGP Autonmous Systems | E1: BGP Community Allocations
E2: Cisco SSE Origin - 53457:55 (55XX)
E3: Meraki Origin - 53457:44 (44XX)
A4: Site | B4: Router Name | C4: BGP ASN | E4: Azure Origin - 53457:33 (33XX)
E6: Cisco SSE Origin - 53457:55 (55XX)
E7: Cisco Site | F7: Cisco Region | G7: SSE DC Type | H7: Cisco Canonical Site Name | I7: Value | J7: Added By Device: | K7: Purpose
A8: Azure Central | E8: ANY | F8: ANY | G8: ANY | H8: ANY | I8: 53457:55 | K8: All SSE prefixes
E9: ANY | F9: us-east-1 | G9: EDC_DCV2 | H9: ANY | I9: 53457:5501 | K9: ALL US-EAST-1
A10: Azure Central | E10: MIAMI-2 | F10: us-east-1 | G10: EDC_DCV2 | H10: prod_csc_us-east-1_1_0 | I10: 53457:5502 | J10: 025-AZ-EAST-US-RTR01
E11: RESTON-1 | F11: us-east-1 | G11: EDC_DCV2 | H11: prod_csc_us-east-1_1_1 | I11: 53457:5503 | J11: 025-AZ-EAST-US-RTR01
E12: ANY | F12: us-west-1 | G12: EDC_DCV2 | H12: ANY | I12: 53457:5504 | K12: ALL US-WEST-1
E13: LOSANGELES-2 | F13: us-west-1 | G13: EDC_DCV2 | H13: prod_csc_us-west-1_1_0 | I13: 53457:5505
E14: SANJOSE-6 | F14: us-west-1 | G14: EDC_DCV2 | H14: prod_csc_us-west-1_1_1 | I14: 53457:5506
E15: ANY | F15: us-east-2 | G15: VEDC_AWS | H15: ANY | I15: 53457:5507 | K15: ALL US-EAST-2
E16: COLUMBUS-1 | F16: us-east-2 | G16: VEDC_AWS | H16: prod_aws_us-east-2_1_0 | I16: 53457:5508
E17: COLUMBUS-2 | F17: us-east-2 | G17: VEDC_AWS | H17: prod_aws_us-east-2_1_1 | I17: 53457:5509
E18: ANY | F18: us-west-2 | G18: VEDC_AWS | H18: ANY | I18: 53457:5510 | K18: ALL US-WEST-2
E19: PORTLAND-1 | F19: us-west-2 | G19: VEDC_AWS | H19: prod_aws_us-west-2_1_0 | I19: 53457:5511
E20: PORTLAND-2 | F20: us-west-2 | G20: VEDC_AWS | H20: prod_aws_us-west-2_1_1 | I20: 53457:5512
E22: Meraki SD-WAN Origin - 1234:2XX
E23: vMX Peer Router | G23: Cloud Region | H23: Division | I23: Value
E24: ANY | G24: ANY | H24: ANY | I24: 1234:200 | K24: Any SD-WAN prefix
E25: ANY | G25: ANY | H25: Retail | I25: 1234:201 | K25: Any Retail SD-WAN prefix
E26: ANY | G26: ANY | H26: BSG | I26: 1234:202 | K26: Any BSG SD-WAN prefix
E27: name | G27: AZ-EAST
E29: Azure East 1 Origin - 1234:3XX

Sheet _data
A1: SSE DCs | C1: SSE Cities | G1: YES-NO | H1: Prefix Categories | J1: Regions
A2: prod_csc_us-east-1_1_0 | C2: MIAMI-2 | D2: =_xlfn.TEXTJOIN(" - ",TRUE, A2,C2) -> prod_csc_us-east-1_1_0 - MIAMI-2 | G2: Yes | H2: CISCO_SSE | J2: MERAKI_RETAIL
A3: prod_csc_us-east-1_1_1 | C3: RESTON-1 | D3: =_xlfn.TEXTJOIN(" - ",TRUE, A3,C3) -> prod_csc_us-east-1_1_1 - RESTON-1 | G3: No | H3: MERAKI | J3: MERAKI_BSG
A4: prod_csc_us-west-1_1_0 | C4: LOSANGELES-2 | D4: =_xlfn.TEXTJOIN(" - ",TRUE, A4,C4) -> prod_csc_us-west-1_1_0 - LOSANGELES-2 | H4: AZURE | J4: AZURE_EAST1
A5: prod_csc_us-west-1_1_1 | C5: SANJOSE-6 | D5: =_xlfn.TEXTJOIN(" - ",TRUE, A5,C5) -> prod_csc_us-west-1_1_1 - SANJOSE-6 | J5: AZURE_EAST2
A6: prod_aws_us-east-2_1_0 | C6: COLUMBUS-1 | D6: =_xlfn.TEXTJOIN(" - ",TRUE, A6,C6) -> prod_aws_us-east-2_1_0 - COLUMBUS-1 | J6: AWS_EAST2
A7: prod_aws_us-east-2_1_1 | C7: COLUMBUS-2 | D7: =_xlfn.TEXTJOIN(" - ",TRUE, A7,C7) -> prod_aws_us-east-2_1_1 - COLUMBUS-2 | J7: AZURE_CENTRAL
A8: prod_aws_us-west-2_1_0 | C8: PORTLAND-1 | D8: =_xlfn.TEXTJOIN(" - ",TRUE, A8,C8) -> prod_aws_us-west-2_1_0 - PORTLAND-1 | J8: N/A
A9: prod_aws_us-west-2_1_1 | C9: PORTLAND-2 | D9: =_xlfn.TEXTJOIN(" - ",TRUE, A9,C9) -> prod_aws_us-west-2_1_1 - PORTLAND-2
A18: Tunnel IP Addresses
A19: {=_xlfn.TEXTSPLIT(IPSEC_BGP_XE_CONFIG!C56, ".")} -> 10 | B19: 7 | C19: 15 | D19: 32 | E19: =_xlfn.TEXTJOIN(".", TRUE,A19,B19,C19,D19 ) -> 10.7.15.32
A20: =A19 -> 10 | B20: =B19 -> 7 | C20: =C19 -> 15 | D20: =D19+1 -> 33 | E20: =_xlfn.TEXTJOIN(".", TRUE,A20,B20,C20,D20 ) -> 10.7.15.33
A21: =A20 -> 10 | B21: =B20 -> 7 | C21: =C20 -> 15 | D21: =D20+1 -> 34 | E21: =_xlfn.TEXTJOIN(".", TRUE,A21,B21,C21,D21 ) -> 10.7.15.34
A22: =A21 -> 10 | B22: =B21 -> 7 | C22: =C21 -> 15 | D22: =D21+1 -> 35 | E22: =_xlfn.TEXTJOIN(".", TRUE,A22,B22,C22,D22 ) -> 10.7.15.35
A23: =A22 -> 10 | B23: =B22 -> 7 | C23: =C22 -> 15 | D23: =D22+1 -> 36 | E23: =_xlfn.TEXTJOIN(".", TRUE,A23,B23,C23,D23 ) -> 10.7.15.36
A24: =A23 -> 10 | B24: =B23 -> 7 | C24: =C23 -> 15 | D24: =D23+1 -> 37 | E24: =_xlfn.TEXTJOIN(".", TRUE,A24,B24,C24,D24 ) -> 10.7.15.37
A25: =A24 -> 10 | B25: =B24 -> 7 | C25: =C24 -> 15 | D25: =D24+1 -> 38 | E25: =_xlfn.TEXTJOIN(".", TRUE,A25,B25,C25,D25 ) -> 10.7.15.38
A26: =A25 -> 10 | B26: =B25 -> 7 | C26: =C25 -> 15 | D26: =D25+1 -> 39 | E26: =_xlfn.TEXTJOIN(".", TRUE,A26,B26,C26,D26 ) -> 10.7.15.39
A27: =A26 -> 10 | B27: =B26 -> 7 | C27: =C26 -> 15 | D27: =D26+1 -> 40 | E27: =_xlfn.TEXTJOIN(".", TRUE,A27,B27,C27,D27 ) -> 10.7.15.40
A28: =A27 -> 10 | B28: =B27 -> 7 | C28: =C27 -> 15 | D28: =D27+1 -> 41 | E28: =_xlfn.TEXTJOIN(".", TRUE,A28,B28,C28,D28 ) -> 10.7.15.41
A29: =A28 -> 10 | B29: =B28 -> 7 | C29: =C28 -> 15 | D29: =D28+1 -> 42 | E29: =_xlfn.TEXTJOIN(".", TRUE,A29,B29,C29,D29 ) -> 10.7.15.42
A30: =A29 -> 10 | B30: =B29 -> 7 | C30: =C29 -> 15 | D30: =D29+1 -> 43 | E30: =_xlfn.TEXTJOIN(".", TRUE,A30,B30,C30,D30 ) -> 10.7.15.43
A31: =A30 -> 10 | B31: =B30 -> 7 | C31: =C30 -> 15 | D31: =D30+1 -> 44 | E31: =_xlfn.TEXTJOIN(".", TRUE,A31,B31,C31,D31 ) -> 10.7.15.44
... A39: =A38 -> 10 | B39: =B38 -> 7 | C39: =C38 -> 15 | D39: =D38+1 -> 52 | E39: =_xlfn.TEXTJOIN(".", TRUE,A39,B39,C39,D39 ) -> 10.7.15.52
E40: =_xlfn.TEXTJOIN(".", TRUE,A40,B40,C40,D40 )
E41: =_xlfn.TEXTJOIN(".", TRUE,A41,B41,C41,D41 )
A42: {=_xlfn.TEXTSPLIT(IPSEC_BGP_XE_CONFIG!C35, ".")} -> 10 | B42: 7 | C42: 15 | D42: 64 | E42: =_xlfn.TEXTJOIN(".", TRUE,A42,B42,C42,D42 ) -> 10.7.15.64
A43: =A42 -> 10 | B43: =B42 -> 7 | C43: =C42 -> 15 | D43: =D42+1 -> 65 | E43: =_xlfn.TEXTJOIN(".", TRUE,A43,B43,C43,D43 ) -> 10.7.15.65
A44: =A43 -> 10 | B44: =B43 -> 7 | C44: =C43 -> 15 | D44: =D43+1 -> 66 | E44: =_xlfn.TEXTJOIN(".", TRUE,A44,B44,C44,D44 ) -> 10.7.15.66
A45: =A44 -> 10 | B45: =B44 -> 7 | C45: =C44 -> 15 | D45: =D44+1 -> 67 | E45: =_xlfn.TEXTJOIN(".", TRUE,A45,B45,C45,D45 ) -> 10.7.15.67
A46: =A45 -> 10 | B46: =B45 -> 7 | C46: =C45 -> 15 | D46: =D45+1 -> 68 | E46: =_xlfn.TEXTJOIN(".", TRUE,A46,B46,C46,D46 ) -> 10.7.15.68
A47: =A46 -> 10 | B47: =B46 -> 7 | C47: =C46 -> 15 | D47: =D46+1 -> 69 | E47: =_xlfn.TEXTJOIN(".", TRUE,A47,B47,C47,D47 ) -> 10.7.15.69
A48: =A47 -> 10 | B48: =B47 -> 7 | C48: =C47 -> 15 | D48: =D47+1 -> 70 | E48: =_xlfn.TEXTJOIN(".", TRUE,A48,B48,C48,D48 ) -> 10.7.15.70
A49: =A48 -> 10 | B49: =B48 -> 7 | C49: =C48 -> 15 | D49: =D48+1 -> 71 | E49: =_xlfn.TEXTJOIN(".", TRUE,A49,B49,C49,D49 ) -> 10.7.15.71
A50: =A49 -> 10 | B50: =B49 -> 7 | C50: =C49 -> 15 | D50: =D49+1 -> 72 | E50: =_xlfn.TEXTJOIN(".", TRUE,A50,B50,C50,D50 ) -> 10.7.15.72
A51: =A50 -> 10 | B51: =B50 -> 7 | C51: =C50 -> 15 | D51: =D50+1 -> 73 | E51: =_xlfn.TEXTJOIN(".", TRUE,A51,B51,C51,D51 ) -> 10.7.15.73
A52: =A51 -> 10 | B52: =B51 -> 7 | C52: =C51 -> 15 | D52: =D51+1 -> 74 | E52: =_xlfn.TEXTJOIN(".", TRUE,A52,B52,C52,D52 ) -> 10.7.15.74
A53: =A52 -> 10 | B53: =B52 -> 7 | C53: =C52 -> 15 | D53: =D52+1 -> 75 | E53: =_xlfn.TEXTJOIN(".", TRUE,A53,B53,C53,D53 ) -> 10.7.15.75
A54: =A53 -> 10 | B54: =B53 -> 7 | C54: =C53 -> 15 | D54: =D53+1 -> 76 | E54: =_xlfn.TEXTJOIN(".", TRUE,A54,B54,C54,D54 ) -> 10.7.15.76
... A61: =A60 -> 10 | B61: =B60 -> 7 | C61: =C60 -> 15 | D61: =D60+1 -> 83 | E61: =_xlfn.TEXTJOIN(".", TRUE,A61,B61,C61,D61 ) -> 10.7.15.83

Sheet _cfg_parts
A1: TEMPLATE | B1: TEXTSPLIT | L1: TEXTJOIN
L2: router1 | Q2: router 2
A3: crypto ikev2 proposal sse-proposal | B3: {=_xlfn.TEXTSPLIT(A3," ",)} -> crypto | C3: ikev2 | D3: proposal | E3: sse-proposal | L3: =_xlfn.TEXTJOIN(" ",TRUE,B3,C3,D3,E3,F3,G3,H3,I3,J3) -> crypto ikev2 proposal sse-proposal | Q3: =_xlfn.TEXTJOIN(" ",TRUE,B3,C3,D3,E3,F3,G3,H3,I3,J3) -> crypto ikev2 proposal sse-proposal
A4: encryption aes-gcm-256 | B4: {=_xlfn.TEXTSPLIT(A4," ",)} -> encryption | C4: aes-gcm-256 | L4: =_xlfn.TEXTJOIN(" ",TRUE,B4,C4,D4,E4,F4,G4,H4,I4,J4) -> encryption aes-gcm-256 | Q4: =_xlfn.TEXTJOIN(" ",TRUE,B4,C4,D4,E4,F4,G4,H4,I4,J4) -> encryption aes-gcm-256
A5: prf sha256 | B5: {=_xlfn.TEXTSPLIT(A5," ",)} -> prf | C5: sha256 | L5: =_xlfn.TEXTJOIN(" ",TRUE,B5,C5,D5,E5,F5,G5,H5,I5,J5) -> prf sha256 | Q5: =_xlfn.TEXTJOIN(" ",TRUE,B5,C5,D5,E5,F5,G5,H5,I5,J5) -> prf sha256
A6: group 20 | B6: {=_xlfn.TEXTSPLIT(A6," ",)} -> group | C6: 20 | L6: =_xlfn.TEXTJOIN(" ",TRUE,B6,C6,D6,E6,F6,G6,H6,I6,J6) -> group 20 | Q6: =_xlfn.TEXTJOIN(" ",TRUE,B6,C6,D6,E6,F6,G6,H6,I6,J6) -> group 20
A7: ! | B7: {=_xlfn.TEXTSPLIT(A7," ",)} -> ! | L7: =_xlfn.TEXTJOIN(" ",TRUE,B7,C7,D7,E7,F7,G7,H7,I7,J7) -> ! | Q7: =_xlfn.TEXTJOIN(" ",TRUE,B7,C7,D7,E7,F7,G7,H7,I7,J7) -> !
A8: crypto ikev2 policy sse-policy | B8: {=_xlfn.TEXTSPLIT(A8," ",)} -> crypto | C8: ikev2 | D8: policy | E8: sse-policy | L8: =_xlfn.TEXTJOIN(" ",TRUE,B8,C8,D8,E8,F8,G8,H8,I8,J8) -> crypto ikev2 policy sse-policy | Q8: =_xlfn.TEXTJOIN(" ",TRUE,B8,C8,D8,E8,F8,G8,H8,I8,J8) -> crypto ikev2 policy sse-policy
A9: proposal sse-proposal | B9: {=_xlfn.TEXTSPLIT(A9," ",)} -> proposal | C9: sse-proposal | L9: =_xlfn.TEXTJOIN(" ",TRUE,B9,C9,D9,E9,F9,G9,H9,I9,J9) -> proposal sse-proposal | Q9: =_xlfn.TEXTJOIN(" ",TRUE,B9,C9,D9,E9,F9,G9,H9,I9,J9) -> proposal sse-proposal
A10: ! | B10: {=_xlfn.TEXTSPLIT(A10," ",)} -> ! | L10: =_xlfn.TEXTJOIN(" ",TRUE,B10,C10,D10,E10,F10,G10,H10,I10,J10) -> ! | Q10: =_xlfn.TEXTJOIN(" ",TRUE,B10,C10,D10,E10,F10,G10,H10,I10,J10) -> !
A11: crypto ikev2 keyring sse-kr | B11: {=_xlfn.TEXTSPLIT(A11," ",)} -> crypto | C11: ikev2 | D11: keyring | E11: sse-kr | L11: =_xlfn.TEXTJOIN(" ",TRUE,B11,C11,D11,E11,F11,G11,H11,I11,J11) -> crypto ikev2 keyring sse-kr | Q11: =_xlfn.TEXTJOIN(" ",TRUE,B11,C11,D11,E11,F11,G11,H11,I11,J11) -> crypto ikev2 keyring sse-kr
A12: peer sse-secondary | B12: {=_xlfn.TEXTSPLIT(A12," ",)} -> peer | C12: sse-secondary | L12: =_xlfn.TEXTJOIN(" ",TRUE,B12,C12,D12,E12,F12,G12,H12,I12,J12) -> peer sse-secondary | Q12: =_xlfn.TEXTJOIN(" ",TRUE,B12,C12,D12,E12,F12,G12,H12,I12,J12) -> peer sse-secondary
A13: address X.X.X.X | B13: {=_xlfn.TEXTSPLIT(A13," ",)} | C13: address | D13: X.X.X.X | L13: =_xlfn.TEXTJOIN(" ",TRUE,B13,C13,IPSEC_BGP_XE_CONFIG!C12,E13,F13,G13,H13,I13,J13) -> address 3.140.13.195 | Q13: =_xlfn.TEXTJOIN(" ",TRUE,B13,C13,IPSEC_BGP_XE_CONFIG!C24,E13,F13,G13,H13,I13,J13) -> address 3.140.13.195
A14: pre-shared-key local | B14: {=_xlfn.TEXTSPLIT(A14," ",)} | C14: pre-shared-key | D14: local | L14: =_xlfn.TEXTJOIN(" ",TRUE,B14,C14,D14,IPSEC_BGP_XE_CONFIG!C32,F14,G14,H14,I14,J14) -> pre-shared-key local ll0wN3t3ng123456 | Q14: =_xlfn.TEXTJOIN(" ",TRUE,B14,C14,D14,IPSEC_BGP_XE_CONFIG!C32,F14,G14,H14,I14,J14) -> pre-shared-key local ll0wN3t3ng123456
A15: pre-shared-key remote | B15: {=_xlfn.TEXTSPLIT(A15," ",)} | C15: pre-shared-key | D15: remote | L15: =_xlfn.TEXTJOIN(" ",TRUE,B15,C15,D15,IPSEC_BGP_XE_CONFIG!C32,F15,G15,H15,I15,J15) -> pre-shared-key remote ll0wN3t3ng123456 | Q15: =_xlfn.TEXTJOIN(" ",TRUE,B15,C15,D15,IPSEC_BGP_XE_CONFIG!C32,F15,G15,H15,I15,J15) -> pre-shared-key remote ll0wN3t3ng123456
A16: ! | B16: {=_xlfn.TEXTSPLIT(A16," ",)} -> ! | L16: =_xlfn.TEXTJOIN(" ",TRUE,B16,C16,D16,E16,F16,G16,H16,I16,J16) -> ! | Q16: =_xlfn.TEXTJOIN(" ",TRUE,B16,C16,D16,E16,F16,G16,H16,I16,J16) -> !
A17: peer sse-primary | B17: {=_xlfn.TEXTSPLIT(A17," ",)} -> peer | C17: sse-primary | L17: =_xlfn.TEXTJOIN(" ",TRUE,B17,C17,D17,E17,F17,G17,H17,I17,J17) -> peer sse-primary | Q17: =_xlfn.TEXTJOIN(" ",TRUE,B17,C17,D17,E17,F17,G17,H17,I17,J17) -> peer sse-primary
A18: address X.X.X.X | B18: {=_xlfn.TEXTSPLIT(A18," ",)} | C18: address | D18: X.X.X.X | L18: =_xlfn.TEXTJOIN(" ",TRUE,B18,C18,IPSEC_BGP_XE_CONFIG!C8,E18,F18,G18,H18,I18,J18) -> address 3.141.141.165 | Q18: =_xlfn.TEXTJOIN(" ",TRUE,B18,C18,IPSEC_BGP_XE_CONFIG!C20,E18,F18,G18,H18,I18,J18) -> address 3.141.141.165
A19: pre-shared-key local | B19: {=_xlfn.TEXTSPLIT(A19," ",)} | C19: pre-shared-key | D19: local | L19: =_xlfn.TEXTJOIN(" ",TRUE,B19,C19,D19,IPSEC_BGP_XE_CONFIG!C32,F19,G19,H19,I19,J19) -> pre-shared-key local ll0wN3t3ng123456 | Q19: =_xlfn.TEXTJOIN(" ",TRUE,B19,C19,D19,IPSEC_BGP_XE_CONFIG!C32,F19,G19,H19,I19,J19) -> pre-shared-key local ll0wN3t3ng123456
A20: pre-shared-key remote | B20: {=_xlfn.TEXTSPLIT(A20," ",)} | C20: pre-shared-key | D20: remote | L20: =_xlfn.TEXTJOIN(" ",TRUE,B20,C20,D20,IPSEC_BGP_XE_CONFIG!C32,F20,G20,H20,I20,J20) -> pre-shared-key remote ll0wN3t3ng123456 | Q20: =_xlfn.TEXTJOIN(" ",TRUE,B20,C20,D20,IPSEC_BGP_XE_CONFIG!C32,F20,G20,H20,I20,J20) -> pre-shared-key remote ll0wN3t3ng123456
A21: ! | B21: {=_xlfn.TEXTSPLIT(A21," ",)} -> ! | L21: =_xlfn.TEXTJOIN(" ",TRUE,B21,C21,D21,E21,F21,G21,H21,I21,J21) -> ! | Q21: =_xlfn.TEXTJOIN(" ",TRUE,B21,C21,D21,E21,F21,G21,H21,I21,J21) -> !
A22: ! | B22: {=_xlfn.TEXTSPLIT(A22," ",)} -> ! | L22: =_xlfn.TEXTJOIN(" ",TRUE,B22,C22,D22,E22,F22,G22,H22,I22,J22) -> ! | Q22: =_xlfn.TEXTJOIN(" ",TRUE,B22,C22,D22,E22,F22,G22,H22,I22,J22) -> !
A23: ! | B23: {=_xlfn.TEXTSPLIT(A23," ",)} -> ! | L23: =_xlfn.TEXTJOIN(" ",TRUE,B23,C23,D23,E23,F23,G23,H23,I23,J23) -> ! | Q23: =_xlfn.TEXTJOIN(" ",TRUE,B23,C23,D23,E23,F23,G23,H23,I23,J23) -> !
A24: crypto ikev2 profile sse-primary-1 | B24: {=_xlfn.TEXTSPLIT(A24," ",)} -> crypto | C24: ikev2 | D24: profile | E24: sse-primary-1 | L24: =_xlfn.TEXTJOIN(" ",TRUE,B24,C24,D24,E24,F24,G24,H24,I24,J24) -> crypto ikev2 profile sse-primary-1 | Q24: =_xlfn.TEXTJOIN(" ",TRUE,B24,C24,D24,E24,F24,G24,H24,I24,J24) -> crypto ikev2 profile sse-primary-1
A25: match identity remote address X.X.X.X 255.255.255.255 | B25: {=_xlfn.TEXTSPLIT(A25," ",)} -> match | C25: identity | D25: remote | E25: address | F25: X.X.X.X | G25: 255.255.255.255 | L25: =_xlfn.TEXTJOIN(" ",TRUE,B25,C25,D25,E25,IPSEC_BGP_XE_CONFIG!C8,G25,H25,I25,J25) -> match identity remote address 3.141.141.165 255.255.255.255 | Q25: =_xlfn.TEXTJOIN(" ",TRUE,B25,C25,D25,E25,IPSEC_BGP_XE_CONFIG!C20,G25,H25,I25,J25) -> match identity remote address 3.141.141.165 255.255.255.255
A26: identity local email XXX@XXX.COM | B26: {=_xlfn.TEXTSPLIT(A26," ",)} -> identity | C26: local | D26: email | E26: XXX@XXX.COM | L26: =_xlfn.TEXTJOIN(" ",TRUE,B26,C26,D26,IPSEC_BGP_XE_CONFIG!C4&"+tunnel1@"&IPSEC_BGP_XE_CONFIG!C9&"-sse.cisco.com",F26,G26,H26,I26,J26) -> identity local email CiscoIOSA-vHub-CentralUS+tunnel1@8363425-667481483-sse.cisco.com | Q26: =_xlfn.TEXTJOIN(" ",TRUE,B26,C26,D26,IPSEC_BGP_XE_CONFIG!C5&"+tunnel1@"&IPSEC_BGP_XE_CONFIG!C21&"-sse.cisco.com",F26,G26,H26,I26,J26) -> identity local email CiscoIOSB-EastUS-Region+tunnel1@8363425-667398686-sse.cisco.com
A27: authentication remote pre-share | B27: {=_xlfn.TEXTSPLIT(A27," ",)} -> authentication | C27: remote | D27: pre-share | L27: =_xlfn.TEXTJOIN(" ",TRUE,B27,C27,D27,E27,F27,G27,H27,I27,J27) -> authentication remote pre-share | Q27: =_xlfn.TEXTJOIN(" ",TRUE,B27,C27,D27,E27,F27,G27,H27,I27,J27) -> authentication remote pre-share
A28: authentication local pre-share | B28: {=_xlfn.TEXTSPLIT(A28," ",)} -> authentication | C28: local | D28: pre-share | L28: =_xlfn.TEXTJOIN(" ",TRUE,B28,C28,D28,E28,F28,G28,H28,I28,J28) -> authentication local pre-share | Q28: =_xlfn.TEXTJOIN(" ",TRUE,B28,C28,D28,E28,F28,G28,H28,I28,J28) -> authentication local pre-share
A29: keyring local sse-kr | B29: {=_xlfn.TEXTSPLIT(A29," ",)} -> keyring | C29: local | D29: sse-kr | L29: =_xlfn.TEXTJOIN(" ",TRUE,B29,C29,D29,E29,F29,G29,H29,I29,J29) -> keyring local sse-kr | Q29: =_xlfn.TEXTJOIN(" ",TRUE,B29,C29,D29,E29,F29,G29,H29,I29,J29) -> keyring local sse-kr
A30: dpd 10 3 periodic | B30: {=_xlfn.TEXTSPLIT(A30," ",)} -> dpd | C30: 10 | D30: 3 | E30: periodic | L30: =_xlfn.TEXTJOIN(" ",TRUE,B30,C30,D30,E30,F30,G30,H30,I30,J30) -> dpd 10 3 periodic | Q30: =_xlfn.TEXTJOIN(" ",TRUE,B30,C30,D30,E30,F30,G30,H30,I30,J30) -> dpd 10 3 periodic
A31: ! | B31: {=_xlfn.TEXTSPLIT(A31," ",)} -> ! | L31: =_xlfn.TEXTJOIN(" ",TRUE,B31,C31,D31,E31,F31,G31,H31,I31,J31) -> ! | Q31: =_xlfn.TEXTJOIN(" ",TRUE,B31,C31,D31,E31,F31,G31,H31,I31,J31) -> !
A32: crypto ikev2 profile sse-primary-2 | B32: {=_xlfn.TEXTSPLIT(A32," ",)} -> crypto | C32: ikev2 | D32: profile | E32: sse-primary-2 | L32: =_xlfn.TEXTJOIN(" ",TRUE,B32,C32,D32,E32,F32,G32,H32,I32,J32) -> crypto ikev2 profile sse-primary-2 | Q32: =_xlfn.TEXTJOIN(" ",TRUE,B32,C32,D32,E32,F32,G32,H32,I32,J32) -> crypto ikev2 profile sse-primary-2
A33: match identity remote address X.X.X.X 255.255.255.255 | B33: {=_xlfn.TEXTSPLIT(A33," ",)} -> match | C33: identity | D33: remote | E33: address | F33: X.X.X.X | G33: 255.255.255.255 | L33: =_xlfn.TEXTJOIN(" ",TRUE,B33,C33,D33,E33,IPSEC_BGP_XE_CONFIG!C8,G33,H33,I33,J33) -> match identity remote address 3.141.141.165 255.255.255.255 | Q33: =_xlfn.TEXTJOIN(" ",TRUE,B33,C33,D33,E33,IPSEC_BGP_XE_CONFIG!C20,G33,H33,I33,J33) -> match identity remote address 3.141.141.165 255.255.255.255
A34: identity local email XXX@XXX.COM | B34: {=_xlfn.TEXTSPLIT(A34," ",)} -> identity | C34: local | D34: email | E34: XXX@XXX.COM | L34: =_xlfn.TEXTJOIN(" ",TRUE,B26,C26,D26,IPSEC_BGP_XE_CONFIG!C4&"+tunnel2@"&IPSEC_BGP_XE_CONFIG!C9&"-sse.cisco.com",F26,G26,H26,I26,J26) -> identity local email CiscoIOSA-vHub-CentralUS+tunnel2@8363425-667481483-sse.cisco.com | Q34: =_xlfn.TEXTJOIN(" ",TRUE,B26,C26,D26,IPSEC_BGP_XE_CONFIG!C5&"+tunnel2@"&IPSEC_BGP_XE_CONFIG!C21&"-sse.cisco.com",F26,G26,H26,I26,J26) -> identity local email CiscoIOSB-EastUS-Region+tunnel2@8363425-667398686-sse.cisco.com
A35: authentication remote pre-share | B35: {=_xlfn.TEXTSPLIT(A35," ",)} -> authentication | C35: remote | D35: pre-share | L35: =_xlfn.TEXTJOIN(" ",TRUE,B35,C35,D35,E35,F35,G35,H35,I35,J35) -> authentication remote pre-share | Q35: =_xlfn.TEXTJOIN(" ",TRUE,B35,C35,D35,E35,F35,G35,H35,I35,J35) -> authentication remote pre-share
A36: authentication local pre-share | B36: {=_xlfn.TEXTSPLIT(A36," ",)} -> authentication | C36: local | D36: pre-share | L36: =_xlfn.TEXTJOIN(" ",TRUE,B36,C36,D36,E36,F36,G36,H36,I36,J36) -> authentication local pre-share | Q36: =_xlfn.TEXTJOIN(" ",TRUE,B36,C36,D36,E36,F36,G36,H36,I36,J36) -> authentication local pre-share
A37: keyring local sse-kr | B37: {=_xlfn.TEXTSPLIT(A37," ",)} -> keyring | C37: local | D37: sse-kr | L37: =_xlfn.TEXTJOIN(" ",TRUE,B37,C37,D37,E37,F37,G37,H37,I37,J37) -> keyring local sse-kr | Q37: =_xlfn.TEXTJOIN(" ",TRUE,B37,C37,D37,E37,F37,G37,H37,I37,J37) -> keyring local sse-kr
A38: dpd 10 3 periodic | B38: {=_xlfn.TEXTSPLIT(A38," ",)} -> dpd | C38: 10 | D38: 3 | E38: periodic | L38: =_xlfn.TEXTJOIN(" ",TRUE,B38,C38,D38,E38,F38,G38,H38,I38,J38) -> dpd 10 3 periodic | Q38: =_xlfn.TEXTJOIN(" ",TRUE,B38,C38,D38,E38,F38,G38,H38,I38,J38) -> dpd 10 3 periodic
A39: ! | B39: {=_xlfn.TEXTSPLIT(A39," ",)} -> ! | L39: =_xlfn.TEXTJOIN(" ",TRUE,B39,C39,D39,E39,F39,G39,H39,I39,J39) -> ! | Q39: =_xlfn.TEXTJOIN(" ",TRUE,B39,C39,D39,E39,F39,G39,H39,I39,J39) -> !
A40: crypto ikev2 profile sse-secondary-1 | B40: {=_xlfn.TEXTSPLIT(A40," ",)} -> crypto | C40: ikev2 | D40: profile | E40: sse-secondary-1 | L40: =_xlfn.TEXTJOIN(" ",TRUE,B40,C40,D40,E40,F40,G40,H40,I40,J40) -> crypto ikev2 profile sse-secondary-1 | Q40: =_xlfn.TEXTJOIN(" ",TRUE,B40,C40,D40,E40,F40,G40,H40,I40,J40) -> crypto ikev2 profile sse-secondary-1
...
